<?xml version="1.0" ?>
<!-- =================================================================================== -->
<!-- |    This document was autogenerated by xacro from /home/rune/catkin_ws/src/kuka_experimental/kuka_kr90uap_support/urdf/kr90r2700prouap.xacro | -->
<!-- |    EDITING THIS FILE BY HAND IS NOT RECOMMENDED                                 | -->
<!-- =================================================================================== -->
<!--Generates a urdf from the macro in kr90r2700proUAP_macro.xacro -->
<robot name="kuka_kr903dp" xmlns:xacro="http://wiki.ros.org/xacro">
  <!-- LINKS -->
  <!-- base link -->
  <link name="base_link">
    <!-- inertial -->
    <!-- origin xyz="0 0 0" rpy="0 0 0"/ -->
    <!-- color name="green" / -->
    <!-- mass value="2"/ -->
    <!-- inertia ixx="0.01" ixy="0" ixz="0" iyy="0.01" iyz="0" izz="0.01" / -->
    <!-- /inertial -->
    <visual>
      <origin rpy="0 0 0" xyz="0 0 0"/>
      <geometry>
        <mesh filename="package://kuka_kr90uap_support/meshes/kr90r2700pro/visual/base_link.stl"/>
      </geometry>
    </visual>
    <collision>
      <origin rpy="0 0 0" xyz="0 0 0"/>
      <geometry>
        <mesh filename="package://kuka_kr90uap_support/meshes/kr90r2700pro/collision/base_link.stl"/>
      </geometry>
    </collision>
  </link>
  <!-- link 1 (A1) -->
  <link name="link_1">
    <inertial>
      <origin rpy="0 0 0" xyz="0 0 0"/>
      <color name="blue"/>
      <mass value="2"/>
      <inertia ixx="0.01" ixy="0" ixz="0" iyy="0.01" iyz="0" izz="0.01"/>
    </inertial>
    <visual>
      <origin rpy="0 0 0" xyz="0 0 0"/>
      <geometry>
        <mesh filename="package://kuka_kr90uap_support/meshes/kr90r2700pro/visual/link_1.stl"/>
      </geometry>
    </visual>
    <collision>
      <origin rpy="0 0 0" xyz="0 0 0"/>
      <geometry>
        <mesh filename="package://kuka_kr90uap_support/meshes/kr90r2700pro/collision/link_1.stl"/>
      </geometry>
    </collision>
  </link>
  <!-- link 2 -->
  <link name="link_2">
    <inertial>
      <origin rpy="0 0 0" xyz="0 0 0"/>
      <color name="green"/>
      <mass value="2"/>
      <inertia ixx="0.01" ixy="0" ixz="0" iyy="0.01" iyz="0" izz="0.01"/>
    </inertial>
    <visual>
      <origin rpy="0 0 0" xyz="0 0 0"/>
      <geometry>
        <mesh filename="package://kuka_kr90uap_support/meshes/kr90r2700pro/visual/link_2.stl"/>
      </geometry>
    </visual>
    <collision>
      <origin rpy="0 0 0" xyz="0 0 0"/>
      <geometry>
        <mesh filename="package://kuka_kr90uap_support/meshes/kr90r2700pro/collision/link_2.stl"/>
      </geometry>
    </collision>
  </link>
  <!-- link 3 -->
  <link name="link_3">
    <inertial>
      <origin rpy="0 0 0" xyz="0 0 0"/>
      <color name="blue"/>
      <mass value="2"/>
      <inertia ixx="0.01" ixy="0" ixz="0" iyy="0.01" iyz="0" izz="0.01"/>
    </inertial>
    <visual>
      <origin rpy="0 0 0" xyz="0 0 0"/>
      <geometry>
        <mesh filename="package://kuka_kr90uap_support/meshes/kr90r2700pro/visual/link_3.stl"/>
      </geometry>
    </visual>
    <collision>
      <origin rpy="0 0 0" xyz="0 0 0"/>
      <geometry>
        <mesh filename="package://kuka_kr90uap_support/meshes/kr90r2700pro/collision/link_3.stl"/>
      </geometry>
    </collision>
  </link>
  <!-- link 4 -->
  <link name="link_4">
    <inertial>
      <origin rpy="0 0 0" xyz="0 0 0"/>
      <color name="green"/>
      <mass value="2"/>
      <inertia ixx="0.01" ixy="0" ixz="0" iyy="0.01" iyz="0" izz="0.01"/>
    </inertial>
    <visual>
      <origin rpy="0 0 0" xyz="0 0 0"/>
      <geometry>
        <mesh filename="package://kuka_kr90uap_support/meshes/kr90r2700pro/visual/link_4.stl"/>
      </geometry>
    </visual>
    <collision>
      <origin rpy="0 0 0" xyz="0 0 0"/>
      <geometry>
        <mesh filename="package://kuka_kr90uap_support/meshes/kr90r2700pro/collision/link_4.stl"/>
      </geometry>
    </collision>
  </link>
  <!-- link 5 -->
  <link name="link_5">
    <inertial>
      <origin rpy="0 0 0" xyz="0 0 0"/>
      <color name="blue"/>
      <mass value="2"/>
      <inertia ixx="0.01" ixy="0" ixz="0" iyy="0.01" iyz="0" izz="0.01"/>
    </inertial>
    <visual>
      <origin rpy="0 0 0" xyz="0 0 0"/>
      <geometry>
        <mesh filename="package://kuka_kr90uap_support/meshes/kr90r2700pro/visual/link_5.stl"/>
      </geometry>
    </visual>
    <collision>
      <origin rpy="0 0 0" xyz="0 0 0"/>
      <geometry>
        <mesh filename="package://kuka_kr90uap_support/meshes/kr90r2700pro/collision/link_5.stl"/>
      </geometry>
    </collision>
  </link>
  <!-- link 6 -->
  <link name="link_6">
    <inertial>
      <origin rpy="0 0 0" xyz="0 0 0"/>
      <mass value="2"/>
      <inertia ixx="0.01" ixy="0" ixz="0" iyy="0.01" iyz="0" izz="0.01"/>
    </inertial>
    <visual>
      <origin rpy="0 0 0" xyz="0 0 0"/>
      <geometry>
        <mesh filename="package://kuka_kr90_support/meshes/kr90r2700pro/visual/link_6.stl"/>
      </geometry>
    </visual>
    <collision>
      <origin rpy="0 0 0" xyz="0 0 0"/>
      <geometry>
        <mesh filename="package://kuka_kr90_support/meshes/kr90r2700pro/collision/link_6.stl"/>
      </geometry>
    </collision>
  </link>
  <!-- link 7 - UAP kuka 3dp extrusion head -->
  <link name="link_7">
    <inertial>
      <origin rpy="0 0 0" xyz="0 0 0"/>
      <mass value="10"/> <!--rando number-->
      <inertia ixx="0.01" ixy="0" ixz="0" iyy="0.01" iyz="0" izz="0.01"/>
    </inertial>
    <visual>
      <origin rpy="0 0 0" xyz="0 0 0"/>
      <geometry>
        <mesh filename="package://kuka_kr903dp_support/meshes/visual/Extruder_wHopper_R6.dae" scale="0.001 0.001 0.001"/>
      </geometry>
    </visual>
    <collision>
      <origin rpy="0 0 0" xyz="0 0 0"/>
      <geometry>
        <mesh filename="package://kuka_kr903dp_support/meshes/collision/Extruder_wHopper_R6.stl"/>
      </geometry>
    </collision>
  </link>
  <link name="extrude_eef"/>
  <!-- tool 0 -->
  <!-- This frame corresponds to the $FLANGE coordinate system in KUKA KRC controllers. -->
  <link name="tool0"/>
  <!-- END LINKS -->
  <!-- JOINTS -->
  <!-- joint 1 (A1) -->
  <joint name="joint_a1" type="revolute">
    <origin rpy="0 0 0" xyz="0 0 0.675"/>
    <parent link="base_link"/>
    <child link="link_1"/>
    <axis xyz="0 0 -1"/>
    <limit effort="0" lower="-3.22885911619" upper="3.22885911619" velocity="2.37364778271"/>
  </joint>
  <!-- joint 2 (A2) -->
  <joint name="joint_a2" type="revolute">
    <origin rpy="0 1.57079632679 0" xyz="0.35 0 0"/>
    <parent link="link_1"/>
    <child link="link_2"/>
    <axis xyz="0 1 0"/>
    <limit effort="0" lower="-2.44346095279" upper="-0.0872664625997" velocity="2.26892802759"/>
    <!-- limit effort="0" lower="${-DEG2RAD * 50}" upper="${DEG2RAD * 85}" velocity="${DEG2RAD * 130}"/ -->
  </joint>
  <!-- joint 3 (A3) -->
  <joint name="joint_a3" type="revolute">
    <origin rpy="0 -1.57079632679 0" xyz="0 0 1.150"/>
    <parent link="link_2"/>
    <child link="link_3"/>
    <axis xyz="0 1 0"/>
    <limit effort="0" lower="-2.09439510239" upper="2.70526034059" velocity="2.09439510239"/>
    <!-- limit effort="0" lower="${-DEG2RAD * 210}" upper="${DEG2RAD * 65}" velocity="${DEG2RAD * 120}"/ -->
  </joint>
  <!-- joint 4 (A4) -->
  <joint name="joint_a4" type="revolute">
    <origin rpy="0 0 0" xyz="1.20 0 -0.041"/>
    <parent link="link_3"/>
    <child link="link_4"/>
    <axis xyz="-1 0 0"/>
    <limit effort="0" lower="-3.490658504" upper="3.490658504" velocity="5.09636141582"/>
  </joint>
  <!-- joint 5 (A5) -->
  <joint name="joint_a5" type="revolute">
    <origin rpy="0 0 0" xyz="0 0 0"/>
    <parent link="link_4"/>
    <child link="link_5"/>
    <axis xyz="0 1 0"/>
    <limit effort="0" lower="-2.18166156499" upper="2.18166156499" velocity="4.50294947015"/>
  </joint>
  <!-- joint 6 (A6) -->
  <joint name="joint_a6" type="revolute">
    <origin rpy="0 0 0" xyz="0 0 0"/>
    <parent link="link_5"/>
    <child link="link_6"/>
    <axis xyz="-1 0 0"/>
    <limit effort="0" lower="-6.10865238198" upper="6.10865238198" velocity="4.95673507566"/>
  </joint>
  <!-- joint 7 (A7) -->
  <joint name="joint_a7" type="fixed">
    <origin rpy="0 0 0" xyz="0 0 0"/>
    <parent link="tool0"/>
    <child link="link_7"/>
  </joint>
  <!-- tool frame - fixed frame -->
  <joint name="joint_a6-tool0" type="fixed">
    <parent link="link_6"/>
    <child link="tool0"/>
    <origin rpy="0 1.57079632679 0" xyz="0.215 0 0"/>
  </joint>
  <!-- extruder eef frame -->
  <joint name="joint_extrude_eef" type="fixed">
    <parent link="link_7"/>
    <child link="extrude_eef"/>
    <!-- <origin rpy="0 0 0" xyz="0.17576813 0.0086262 0.2244498"/> -->
    <origin rpy="0 0 0" xyz="0.8 0.0086262 0.1"/>
  </joint>
  <!--joint name="joint_a7-tool0" type="fixed">
    <parent link="link_7"/>
    <child link="tool0"/>
    <origin rpy="0 0 0" xyz="0 0 0"/>
  </joint -->
  <!-- END JOINTS -->
  <!-- ROS base_link to KUKA $ROBROOT coordinate system transform -->
  <link name="base"/>
  <joint name="base_link-base" type="fixed">
    <origin rpy="0 0 0" xyz="0 0 0"/>
    <parent link="base_link"/>
    <child link="base"/>
  </joint>
</robot>

