<?xml version="1.0"?>
<robot xmlns:xacro="http://wiki.ros.org/xacro">

  <xacro:property name="DEG2RAD" value="0.017453292519943295"/>

  <xacro:macro name="kuka_kr90r2700prouap" params="prefix">
    <!-- LINKS -->
    <!-- base link -->
    <link name="${prefix}base_link">
      <!-- inertial -->
        <!-- origin xyz="0 0 0" rpy="0 0 0"/ -->
        <!-- color name="green" / -->
        <!-- mass value="2"/ -->
        <!-- inertia ixx="0.01" ixy="0" ixz="0" iyy="0.01" iyz="0" izz="0.01" / -->
      <!-- /inertial -->
      <visual>
        <origin xyz="0 0 0" rpy="0 0 0"/>
        <geometry>
          <mesh filename="package://kuka_kr90uap_support/meshes/kr90r2700pro/visual/base_link.stl" />
        </geometry>
      </visual>
      <collision>
        <origin xyz="0 0 0" rpy="0 0 0"/>
        <geometry>
          <mesh filename="package://kuka_kr90uap_support/meshes/kr90r2700pro/collision/base_link.stl" />
        </geometry>
      </collision>
    </link>
    <!-- link 1 (A1) -->
    <link name="${prefix}link_1">
      <inertial>
        <origin xyz="0 0 0" rpy="0 0 0"/>
        <color name="blue" />
        <mass value="2"/>
        <inertia ixx="0.01" ixy="0" ixz="0" iyy="0.01" iyz="0" izz="0.01" />
      </inertial>
      <visual>
        <origin xyz="0 0 0" rpy="0 0 0"/>
        <geometry>
          <mesh filename="package://kuka_kr90uap_support/meshes/kr90r2700pro/visual/link_1.stl" />
        </geometry>
      </visual>
      <collision>
        <origin xyz="0 0 0" rpy="0 0 0"/>
        <geometry>
          <mesh filename="package://kuka_kr90uap_support/meshes/kr90r2700pro/collision/link_1.stl" />
        </geometry>
      </collision>
    </link>
    <!-- link 2 -->
    <link name="${prefix}link_2">
      <inertial>
        <origin xyz="0 0 0" rpy="0 0 0"/>
        <color name="green" />
        <mass value="2"/>
        <inertia ixx="0.01" ixy="0" ixz="0" iyy="0.01" iyz="0" izz="0.01" />
      </inertial>
      <visual>
        <origin xyz="0 0 0" rpy="0 0 0"/>
        <geometry>
          <mesh filename="package://kuka_kr90uap_support/meshes/kr90r2700pro/visual/link_2.stl"/>
        </geometry>
      </visual>
      <collision>
        <origin xyz="0 0 0" rpy="0 0 0"/>
        <geometry>
          <mesh filename="package://kuka_kr90uap_support/meshes/kr90r2700pro/collision/link_2.stl" />
        </geometry>
      </collision>
    </link>
    <!-- link 3 -->
    <link name="${prefix}link_3">
      <inertial>
        <origin xyz="0 0 0" rpy="0 0 0"/>
        <color name="blue" />
        <mass value="2"/>
        <inertia ixx="0.01" ixy="0" ixz="0" iyy="0.01" iyz="0" izz="0.01" />
      </inertial>
      <visual>
        <origin xyz="0 0 0" rpy="0 0 0"/>
        <geometry>
          <mesh filename="package://kuka_kr90uap_support/meshes/kr90r2700pro/visual/link_3.stl" />
        </geometry>
      </visual>
      <collision>
        <origin xyz="0 0 0" rpy="0 0 0"/>
        <geometry>
          <mesh filename="package://kuka_kr90uap_support/meshes/kr90r2700pro/collision/link_3.stl" />
        </geometry>
      </collision>
    </link>
    <!-- link 4 -->
    <link name="${prefix}link_4">
      <inertial>
        <origin xyz="0 0 0" rpy="0 0 0"/>
        <color name="green" />
        <mass value="2"/>
        <inertia ixx="0.01" ixy="0" ixz="0" iyy="0.01" iyz="0" izz="0.01" />
      </inertial>
      <visual>
        <origin xyz="0 0 0" rpy="0 0 0"/>
        <geometry>
          <mesh filename="package://kuka_kr90uap_support/meshes/kr90r2700pro/visual/link_4.stl" />
        </geometry>
      </visual>
      <collision>
        <origin xyz="0 0 0" rpy="0 0 0"/>
        <geometry>
          <mesh filename="package://kuka_kr90uap_support/meshes/kr90r2700pro/collision/link_4.stl" />
        </geometry>
      </collision>
    </link>
    <!-- link 5 -->
    <link name="${prefix}link_5">
      <inertial>
        <origin xyz="0 0 0" rpy="0 0 0"/>
        <color name="blue" />
        <mass value="2"/>
        <inertia ixx="0.01" ixy="0" ixz="0" iyy="0.01" iyz="0" izz="0.01" />
      </inertial>
      <visual>
        <origin xyz="0 0 0" rpy="0 0 0"/>
        <geometry>
          <mesh filename="package://kuka_kr90uap_support/meshes/kr90r2700pro/visual/link_5.stl" />
        </geometry>
      </visual>
      <collision>
        <origin xyz="0 0 0" rpy="0 0 0"/>
        <geometry>
          <mesh filename="package://kuka_kr90uap_support/meshes/kr90r2700pro/collision/link_5.stl" />
        </geometry>
      </collision>
    </link>
    <!-- link 6 -->
    <link name="${prefix}link_6">
      <inertial>
        <origin xyz="0 0 0" rpy="0 0 0"/>
        <color name="green" />
        <mass value="2"/>
        <inertia ixx="0.01" ixy="0" ixz="0" iyy="0.01" iyz="0" izz="0.01" />
      </inertial>
      <visual>
        <origin xyz="0 0 0" rpy="0 0 0"/>
        <geometry>
          <mesh filename="package://kuka_kr90uap_support/meshes/kr90r2700pro/visual/miller_end_effector.stl" />
        </geometry>
      </visual>
      <collision>
        <origin xyz="0 0 0" rpy="0 0 0"/>
        <geometry>
          <mesh filename="package://kuka_kr90uap_support/meshes/kr90r2700pro/collision/miller_end_effector.stl" />
        </geometry>
      </collision>
    </link>
    <!-- table link -->
    <link name="${prefix}table_link">
      <inertial>
        <origin xyz="0 0 0" rpy="0 0 0"/>
        <color name="green" />
        <mass value="2"/>
        <inertia ixx="0.01" ixy="0" ixz="0" iyy="0.01" iyz="0" izz="0.01" />
      </inertial>
      <visual>
        <origin xyz="0 0 0" rpy="0 0 0"/>
        <geometry>
          <mesh filename="package://kuka_kr90uap_support/meshes/kr90r2700pro/visual/table_base.stl" />
        </geometry>
      </visual>
      <collision>
        <origin xyz="0 0 0" rpy="0 0 0"/>
        <geometry>
          <mesh filename="package://kuka_kr90uap_support/meshes/kr90r2700pro/collision/table_base.stl" />
        </geometry>
      </collision>
    </link>
    <!-- link 7 -->
    <link name="${prefix}link_7">
      <inertial>
        <origin xyz="0 0 0" rpy="0 0 0"/>
        <color name="blue" />
        <mass value="2"/>
        <inertia ixx="0.01" ixy="0" ixz="0" iyy="0.01" iyz="0" izz="0.01" />
      </inertial>
      <visual>
        <origin xyz="0 0 0" rpy="0 0 0"/>
        <geometry>
          <mesh filename="package://kuka_kr90uap_support/meshes/kr90r2700pro/visual/table_link.stl" />
        </geometry>
      </visual>
      <collision>
        <origin xyz="0 0 0" rpy="0 0 0"/>
        <geometry>
          <mesh filename="package://kuka_kr90uap_support/meshes/kr90r2700pro/collision/table_link.stl" />
        </geometry>
      </collision>
    </link>
    <!-- tool 0 -->
    <!-- This frame corresponds to the $FLANGE coordinate system in KUKA KRC controllers. -->
    <link name="${prefix}tool0"/>
    <!-- END LINKS -->

    <!-- JOINTS -->
    <!-- joint 1 (A1) -->
    <joint name="${prefix}joint_a1" type="revolute">
      <origin xyz="0 0 0.675" rpy="0 0 0"/>
      <parent link="${prefix}base_link"/>
      <child link="${prefix}link_1"/>
      <axis xyz="0 0 -1"/>
      <limit effort="0" lower="${-DEG2RAD * 185}" upper="${DEG2RAD * 185}" velocity="${DEG2RAD * 136}"/>
    </joint>
    <!-- joint 2 (A2) -->
    <joint name="${prefix}joint_a2" type="revolute">
      <origin xyz="0.35 0 0" rpy="0 ${DEG2RAD * 90} 0"/>
      <parent link="${prefix}link_1"/>
      <child link="${prefix}link_2"/>
      <axis xyz="0 1 0"/>
      <limit effort="0" lower="${-DEG2RAD * 140}" upper="${-DEG2RAD * 5}" velocity="${DEG2RAD * 130}"/><!-- limit effort="0" lower="${-DEG2RAD * 50}" upper="${DEG2RAD * 85}" velocity="${DEG2RAD * 130}"/ -->
    </joint>
    <!-- joint 3 (A3) -->
    <joint name="${prefix}joint_a3" type="revolute">
      <origin xyz="0 0 1.150" rpy="0 ${-DEG2RAD * 90} 0"/>
      <parent link="${prefix}link_2"/>
      <child link="${prefix}link_3"/>
      <axis xyz="0 1 0"/>
      <limit effort="0" lower="${-DEG2RAD * 120}" upper="${DEG2RAD * 155}" velocity="${DEG2RAD * 120}"/><!-- limit effort="0" lower="${-DEG2RAD * 210}" upper="${DEG2RAD * 65}" velocity="${DEG2RAD * 120}"/ -->
    </joint>
    <!-- joint 4 (A4) -->
    <joint name="${prefix}joint_a4" type="revolute">
      <origin xyz="1.20 0 -0.041" rpy="0 0 0"/>
      <parent link="${prefix}link_3"/>
      <child link="${prefix}link_4"/>
      <axis xyz="-1 0 0"/>
      <limit effort="0" lower="${-DEG2RAD * 200}" upper="${DEG2RAD * 200}" velocity="${DEG2RAD * 292}"/>
    </joint>
    <!-- joint 5 (A5) -->
    <joint name="${prefix}joint_a5" type="revolute">
      <origin xyz="0 0 0" rpy="0 0 0"/>
      <parent link="${prefix}link_4"/>
      <child link="${prefix}link_5"/>
      <axis xyz="0 1 0"/>
      <limit effort="0" lower="${-DEG2RAD * 125}" upper="${DEG2RAD * 125}" velocity="${DEG2RAD * 258}"/>
    </joint>
    <!-- joint 6 (A6) -->
    <joint name="${prefix}joint_a6" type="revolute">
      <origin xyz="0.215 0 0" rpy="0 0 0"/>
      <parent link="${prefix}link_5"/>
      <child link="${prefix}link_6"/>
      <axis xyz="-1 0 0"/>
      <limit effort="0" lower="${-DEG2RAD * 200}" upper="${DEG2RAD * 200}" velocity="${DEG2RAD * 284}"/>
    </joint>
    <!-- tool frame - fixed frame -->
    <joint name="${prefix}joint_a6-tool0" type="fixed">
      <parent link="${prefix}link_6"/>
      <child link="${prefix}tool0"/>
      <origin xyz="0 0 0" rpy="0 ${DEG2RAD * 90} 0"/>
    </joint>
    <joint name="${prefix}table-base" type="fixed">
      <origin xyz="2.0 0 -0.7" rpy="0 0 0"/>
      <parent link="${prefix}base_link"/>
      <child link="${prefix}table_link"/>
    </joint>
    <!-- joint 7 (T1) -->
    <joint name="${prefix}joint_t1" type="revolute">
      <origin xyz="0 0 0" rpy="0 0 0"/>
      <parent link="${prefix}table_link"/>
      <child link="${prefix}link_7"/>
      <axis xyz="0 0 -1"/>
      <limit effort="0" lower="${-DEG2RAD * 360}" upper="${DEG2RAD * 360}" velocity="${DEG2RAD * 136}"/>
    </joint>
    <!--joint name="${prefix}joint_a7-tool0" type="fixed">
      <parent link="${prefix}link_7"/>
      <child link="${prefix}tool0"/>
      <origin xyz="0 0 0" rpy="0 0 0"/>
    </joint -->
    <!-- END JOINTS -->

    <!-- ROS base_link to KUKA $ROBROOT coordinate system transform -->
    <link name="${prefix}base" />
    <joint name="${prefix}base_link-base" type="fixed">
      <origin xyz="0 0 0" rpy="0 0 0"/>
      <parent link="${prefix}base_link"/>
      <child link="${prefix}base"/>
    </joint>
    

  </xacro:macro>
</robot>


