<?xml version="1.0" ?>
<!-- =================================================================================== -->
<!-- |    This document was autogenerated by xacro from urdf/kr90r2700pro.xacro        | -->
<!-- |    EDITING THIS FILE BY HAND IS NOT RECOMMENDED                                 | -->
<!-- =================================================================================== -->
<!--Generates a urdf from the macro in kr90r2700pro_macro.xacro -->
<robot name="kuka_kr90r2700pro" xmlns:xacro="http://wiki.ros.org/xacro">
  <!-- LINKS -->
  <!-- base link -->
  <link name="base_link">
    <inertial>
      <origin rpy="0 0 0" xyz="0 0 0"/>
      <mass value="2"/>
      <inertia ixx="0.01" ixy="0" ixz="0" iyy="0.01" iyz="0" izz="0.01"/>
    </inertial>
    <visual>
      <origin rpy="0 0 0" xyz="0 0 0"/>
      <geometry>
        <mesh filename="package://kuka_kr90_support/meshes/kr90r2700pro/visual/base_link.stl"/>
      </geometry>
    </visual>
    <collision>
      <origin rpy="0 0 0" xyz="0 0 0"/>
      <geometry>
        <mesh filename="package://kuka_kr90_support/meshes/kr90r2700pro/collision/base_link.stl"/>
      </geometry>
    </collision>
  </link>
  <!-- link 1 (A1) -->
  <link name="link_1">
    <inertial>
      <origin rpy="0 0 0" xyz="0 0 0"/>
      <mass value="2"/>
      <inertia ixx="0.01" ixy="0" ixz="0" iyy="0.01" iyz="0" izz="0.01"/>
    </inertial>
    <visual>
      <origin rpy="0 0 0" xyz="0 0 0"/>
      <geometry>
        <mesh filename="package://kuka_kr90_support/meshes/kr90r2700pro/visual/link_1.stl"/>
      </geometry>
    </visual>
    <collision>
      <origin rpy="0 0 0" xyz="0 0 0"/>
      <geometry>
        <mesh filename="package://kuka_kr90_support/meshes/kr90r2700pro/collision/link_1.stl"/>
      </geometry>
    </collision>
  </link>
  <!-- link 2 -->
  <link name="link_2">
    <inertial>
      <origin rpy="0 0 0" xyz="0 0 0"/>
      <mass value="2"/>
      <inertia ixx="0.01" ixy="0" ixz="0" iyy="0.01" iyz="0" izz="0.01"/>
    </inertial>
    <visual>
      <origin rpy="0 0 0" xyz="0 0 0"/>
      <geometry>
        <mesh filename="package://kuka_kr90_support/meshes/kr90r2700pro/visual/link_2.stl"/>
      </geometry>
    </visual>
    <collision>
      <origin rpy="0 0 0" xyz="0 0 0"/>
      <geometry>
        <mesh filename="package://kuka_kr90_support/meshes/kr90r2700pro/collision/link_2.stl"/>
      </geometry>
    </collision>
  </link>
  <!-- link 3 -->
  <link name="link_3">
    <inertial>
      <origin rpy="0 0 0" xyz="0 0 0"/>
      <mass value="2"/>
      <inertia ixx="0.01" ixy="0" ixz="0" iyy="0.01" iyz="0" izz="0.01"/>
    </inertial>
    <visual>
      <origin rpy="0 0 0" xyz="0 0 0"/>
      <geometry>
        <mesh filename="package://kuka_kr90_support/meshes/kr90r2700pro/visual/link_3.stl"/>
      </geometry>
    </visual>
    <collision>
      <origin rpy="0 0 0" xyz="0 0 0"/>
      <geometry>
        <mesh filename="package://kuka_kr90_support/meshes/kr90r2700pro/collision/link_3.stl"/>
      </geometry>
    </collision>
  </link>
  <!-- link 4 -->
  <link name="link_4">
    <inertial>
      <origin rpy="0 0 0" xyz="0 0 0"/>
      <mass value="2"/>
      <inertia ixx="0.01" ixy="0" ixz="0" iyy="0.01" iyz="0" izz="0.01"/>
    </inertial>
    <visual>
      <origin rpy="0 0 0" xyz="0 0 0"/>
      <geometry>
        <mesh filename="package://kuka_kr90_support/meshes/kr90r2700pro/visual/link_4.stl"/>
      </geometry>
    </visual>
    <collision>
      <origin rpy="0 0 0" xyz="0 0 0"/>
      <geometry>
        <mesh filename="package://kuka_kr90_support/meshes/kr90r2700pro/collision/link_4.stl"/>
      </geometry>
    </collision>
  </link>
  <!-- link 5 -->
  <link name="link_5">
    <inertial>
      <origin rpy="0 0 0" xyz="0 0 0"/>
      <mass value="2"/>
      <inertia ixx="0.01" ixy="0" ixz="0" iyy="0.01" iyz="0" izz="0.01"/>
    </inertial>
    <visual>
      <origin rpy="0 0 0" xyz="0 0 0"/>
      <geometry>
        <mesh filename="package://kuka_kr90_support/meshes/kr90r2700pro/visual/link_5.stl"/>
      </geometry>
    </visual>
    <collision>
      <origin rpy="0 0 0" xyz="0 0 0"/>
      <geometry>
        <mesh filename="package://kuka_kr90_support/meshes/kr90r2700pro/collision/link_5.stl"/>
      </geometry>
    </collision>
  </link>
  <!-- link 6 -->
  <link name="link_6">
    <inertial>
      <origin rpy="0 0 0" xyz="0 0 0"/>
      <mass value="2"/>
      <inertia ixx="0.01" ixy="0" ixz="0" iyy="0.01" iyz="0" izz="0.01"/>
    </inertial>
    <visual>
      <origin rpy="0 0 0" xyz="0 0 0"/>
      <geometry>
        <mesh filename="package://kuka_kr90_support/meshes/kr90r2700pro/visual/link_6.stl"/>
      </geometry>
    </visual>
    <collision>
      <origin rpy="0 0 0" xyz="0 0 0"/>
      <geometry>
        <mesh filename="package://kuka_kr90_support/meshes/kr90r2700pro/collision/link_6.stl"/>
      </geometry>
    </collision>
  </link>
  <!-- tool 0 -->
  <!-- This frame corresponds to the $FLANGE coordinate system in KUKA KRC controllers. -->
  <link name="tool0"/>
  <!-- END LINKS -->
  <!-- JOINTS -->
  <!-- joint 1 (A1) -->
  <joint name="joint_a1" type="revolute">
    <origin rpy="0 0 0" xyz="0 0 0.675"/>
    <parent link="base_link"/>
    <child link="link_1"/>
    <axis xyz="0 0 -1"/>
    <limit effort="0" lower="-3.22885911619" upper="3.22885911619" velocity="2.37364778271"/>
  </joint>
  <!-- joint 2 (A2) -->
  <joint name="joint_a2" type="revolute">
    <origin rpy="0 0 0" xyz="0.35 0 0"/>
    <parent link="link_1"/>
    <child link="link_2"/>
    <axis xyz="0 1 0"/>
    <limit effort="0" lower="-0.872664625997" upper="1.4835298642" velocity="2.26892802759"/>
  </joint>
  <!-- joint 3 (A3) -->
  <joint name="joint_a3" type="revolute">
    <origin rpy="0 0 0" xyz="0 0 1.150"/>
    <parent link="link_2"/>
    <child link="link_3"/>
    <axis xyz="0 1 0"/>
    <limit effort="0" lower="-3.66519142919" upper="1.1344640138" velocity="2.09439510239"/>
  </joint>
  <!-- joint 4 (A4) -->
  <joint name="joint_a4" type="revolute">
    <origin rpy="0 0 0" xyz="1.20 0 -0.041"/>
    <parent link="link_3"/>
    <child link="link_4"/>
    <axis xyz="-1 0 0"/>
    <limit effort="0" lower="-6.10865238198" upper="6.10865238198" velocity="5.09636141582"/>
  </joint>
  <!-- joint 5 (A5) -->
  <joint name="joint_a5" type="revolute">
    <origin rpy="0 0 0" xyz="0 0 0"/>
    <parent link="link_4"/>
    <child link="link_5"/>
    <axis xyz="0 1 0"/>
    <limit effort="0" lower="-2.18166156499" upper="2.18166156499" velocity="4.50294947015"/>
  </joint>
  <!-- joint 6 (A6) -->
  <joint name="joint_a6" type="revolute">
    <origin rpy="0 0 0" xyz="0 0 0"/>
    <parent link="link_5"/>
    <child link="link_6"/>
    <axis xyz="-1 0 0"/>
    <limit effort="0" lower="-6.10865238198" upper="6.10865238198" velocity="4.95673507566"/>
  </joint>
  <!-- tool frame - fixed frame -->
  <joint name="joint_a6-tool0" type="fixed">
    <parent link="link_6"/>
    <child link="tool0"/>
    <origin rpy="0 1.57079632679 0" xyz="0.215 0 0"/>
  </joint>
  <!-- END JOINTS -->
  <!-- ROS base_link to KUKA $ROBROOT coordinate system transform -->
  <link name="base"/>
  <joint name="base_link-base" type="fixed">
    <origin rpy="0 0 0" xyz="0 0 0"/>
    <parent link="base"/>
    <child link="base_link"/>
  </joint>
</robot>
